<?xml version="1.0"?>
<robot name="Franka">
    <link name="robot_base">
        <collision name="Franka">
            <origin xyz="-0.516000 0.150000 0.070000" rpy="-3.141593 3.141593 -3.141593" />
            <geometry>
                <mesh filename="file:///home/rosqiu/coppelia_control/src/cs_hardware_interface/urdf/exported_panda_robot_base_coll_1.dae" />
            </geometry>
        </collision>
        <visual name="link">
            <origin xyz="-0.516000 0.150000 0.070000" rpy="-3.141593 3.141593 -3.141593" />
            <geometry>
                <mesh filename="file:///home/rosqiu/coppelia_control/src/cs_hardware_interface/urdf/exported_panda_link_vis_1.dae" />
            </geometry>
            <material name="link_material">
                <color rgba="1.000000 1.000000 1.000000 1.0" />
            </material>
        </visual>
    </link>
    <joint name="panda_joint1" type="revolute">
        <axis xyz="0 0 1" />
        <limit velocity="2.1749997138977" lower="-2.8972465991974" effort="87.0" upper="2.8972465991974" />
        <parent link="robot_base" />
        <child link="link2_resp" />
        <origin xyz="-0.474729 0.150012 0.000000" rpy="-3.141593 3.141593 -3.141593" />
    </joint>
    <link name="link2_resp">
        <inertial>
            <origin xyz="0.000027 -0.031145 0.262891" rpy="-3.141593 3.141593 -3.141593" />
            <inertia ixy="1.8036869099987e-05" ixx="0.23965416449794" izz="0.096472146190744" iyz="0.046543293301451" iyy="0.20795149177852" ixz="1.3128335716866e-05" />
            <mass value="4.9706840515137" />
        </inertial>
        <collision name="link2_resp">
            <origin xyz="0.000023 -0.037262 0.263822" rpy="-3.141593 3.141593 -3.141593" />
            <geometry>
                <mesh filename="file:///home/rosqiu/coppelia_control/src/cs_hardware_interface/urdf/exported_panda_link2_resp_coll_1.dae" />
            </geometry>
        </collision>
        <collision name="link2_resp">
            <origin xyz="0.000023 -0.037262 0.263822" rpy="-3.141593 3.141593 -3.141593" />
            <geometry>
                <mesh filename="file:///home/rosqiu/coppelia_control/src/cs_hardware_interface/urdf/exported_panda_link2_resp_coll_2.dae" />
            </geometry>
        </collision>
        <collision name="link2_resp">
            <origin xyz="0.000023 -0.037262 0.263822" rpy="-3.141593 3.141593 -3.141593" />
            <geometry>
                <mesh filename="file:///home/rosqiu/coppelia_control/src/cs_hardware_interface/urdf/exported_panda_link2_resp_coll_3.dae" />
            </geometry>
        </collision>
        <collision name="link2_resp">
            <origin xyz="0.000023 -0.037262 0.263822" rpy="-3.141593 3.141593 -3.141593" />
            <geometry>
                <mesh filename="file:///home/rosqiu/coppelia_control/src/cs_hardware_interface/urdf/exported_panda_link2_resp_coll_4.dae" />
            </geometry>
        </collision>
        <visual name="link">
            <origin xyz="0.000023 -0.037242 0.263855" rpy="-3.141593 3.141593 -3.141593" />
            <geometry>
                <mesh filename="file:///home/rosqiu/coppelia_control/src/cs_hardware_interface/urdf/exported_panda_link_2_vis_1.dae" />
            </geometry>
            <material name="link_2_material">
                <color rgba="1.000000 1.000000 1.000000 1.0" />
            </material>
        </visual>
    </link>
    <joint name="panda_joint2" type="revolute">
        <axis xyz="0 0 1" />
        <limit velocity="2.1749997138977" lower="-1.7627825737" effort="87.0" upper="1.7627825737" />
        <parent link="link2_resp" />
        <child link="link3_resp" />
        <origin xyz="-0.000000 -0.000000 0.333000" rpy="1.570796 3.141593 3.141593" />
    </joint>
    <link name="link3_resp">
        <inertial>
            <origin xyz="0.000012 -0.070031 0.031073" rpy="-1.570796 3.141593 -3.141593" />
            <inertia ixy="4.6746993616892e-06" ixx="0.021097005907894" izz="0.0083947222563338" iyz="0.0040788476591549" iyy="0.018332235221749" ixz="-9.6899135443004e-07" />
            <mass value="0.64692598581314" />
        </inertial>
        <collision name="link3_resp">
            <origin xyz="0.000013 -0.069030 0.037184" rpy="-1.570796 3.141593 -3.141593" />
            <geometry>
                <mesh filename="file:///home/rosqiu/coppelia_control/src/cs_hardware_interface/urdf/exported_panda_link3_resp_coll_1.dae" />
            </geometry>
        </collision>
        <collision name="link3_resp">
            <origin xyz="0.000013 -0.069030 0.037184" rpy="-1.570796 3.141593 -3.141593" />
            <geometry>
                <mesh filename="file:///home/rosqiu/coppelia_control/src/cs_hardware_interface/urdf/exported_panda_link3_resp_coll_2.dae" />
            </geometry>
        </collision>
        <visual name="link">
            <origin xyz="-0.000003 -0.069076 0.037184" rpy="-1.570796 3.141593 -3.141593" />
            <geometry>
                <mesh filename="file:///home/rosqiu/coppelia_control/src/cs_hardware_interface/urdf/exported_panda_link_3_vis_1.dae" />
            </geometry>
            <material name="link_3_material">
                <color rgba="1.000000 1.000000 1.000000 1.0" />
            </material>
        </visual>
    </link>
    <joint name="panda_joint3" type="revolute">
        <axis xyz="0 0 1" />
        <limit velocity="2.1749997138977" lower="-2.8972465991974" effort="87.0" upper="2.8972465991974" />
        <parent link="link3_resp" />
        <child link="link4_resp" />
        <origin xyz="-0.000000 0.000000 0.000000" rpy="-1.570797 3.141593 -3.141593" />
    </joint>
    <link name="link4_resp">
        <inertial>
            <origin xyz="0.044418 0.025018 0.276461" rpy="-3.141592 3.141593 3.141593" />
            <inertia ixy="-0.0071662360347711" ixx="0.037043165158734" izz="0.037313700213202" iyz="-0.0066345366154784" iyy="0.044600332011806" ixz="-0.012283585683442" />
            <mass value="3.2286040782928" />
        </inertial>
        <collision name="link4_resp">
            <origin xyz="0.041373 0.028168 0.281765" rpy="-3.141592 3.141593 3.141593" />
            <geometry>
                <mesh filename="file:///home/rosqiu/coppelia_control/src/cs_hardware_interface/urdf/exported_panda_link4_resp_coll_1.dae" />
            </geometry>
        </collision>
        <collision name="link4_resp">
            <origin xyz="0.041373 0.028168 0.281765" rpy="-3.141592 3.141593 3.141593" />
            <geometry>
                <mesh filename="file:///home/rosqiu/coppelia_control/src/cs_hardware_interface/urdf/exported_panda_link4_resp_coll_2.dae" />
            </geometry>
        </collision>
        <collision name="link4_resp">
            <origin xyz="0.041373 0.028168 0.281765" rpy="-3.141592 3.141593 3.141593" />
            <geometry>
                <mesh filename="file:///home/rosqiu/coppelia_control/src/cs_hardware_interface/urdf/exported_panda_link4_resp_coll_3.dae" />
            </geometry>
        </collision>
        <collision name="link4_resp">
            <origin xyz="0.041373 0.028168 0.281765" rpy="-3.141592 3.141593 3.141593" />
            <geometry>
                <mesh filename="file:///home/rosqiu/coppelia_control/src/cs_hardware_interface/urdf/exported_panda_link4_resp_coll_4.dae" />
            </geometry>
        </collision>
        <visual name="link">
            <origin xyz="0.041158 0.028089 0.281656" rpy="-3.141592 3.141593 -3.141593" />
            <geometry>
                <mesh filename="file:///home/rosqiu/coppelia_control/src/cs_hardware_interface/urdf/exported_panda_link_4_vis_1.dae" />
            </geometry>
            <material name="link_4_material">
                <color rgba="1.000000 1.000000 1.000000 1.0" />
            </material>
        </visual>
        <visual name="link">
            <origin xyz="0.041158 0.028089 0.281656" rpy="-3.141592 3.141593 -3.141593" />
            <geometry>
                <mesh filename="file:///home/rosqiu/coppelia_control/src/cs_hardware_interface/urdf/exported_panda_link_4_vis_2.dae" />
            </geometry>
            <material name="link_4_material">
                <color rgba="0.250000 0.250000 0.250000 1.0" />
            </material>
        </visual>
    </link>
    <joint name="panda_joint4" type="revolute">
        <axis xyz="0 0 1" />
        <limit velocity="2.1749997138977" lower="-3.0019662380219" effort="87.0" upper="0.0" />
        <parent link="link4_resp" />
        <child link="link5_resp" />
        <origin xyz="0.082500 -0.000000 0.316000" rpy="-1.570796 3.141593 -3.141592" />
    </joint>
    <link name="link5_resp">
        <inertial>
            <origin xyz="-0.036035 0.041072 0.024354" rpy="1.570796 3.141593 3.071779" />
            <inertia ixy="0.0091601974989418" ixx="0.04844892193307" izz="0.047764716548773" iyz="-0.0086501440884625" iyy="0.05816570900911" ixz="0.016026606898086" />
            <mass value="3.5878949165344" />
        </inertial>
        <collision name="link5_resp">
            <origin xyz="-0.038916 0.036337 0.027506" rpy="1.570796 3.141593 3.071779" />
            <geometry>
                <mesh filename="file:///home/rosqiu/coppelia_control/src/cs_hardware_interface/urdf/exported_panda_link5_resp_coll_1.dae" />
            </geometry>
        </collision>
        <collision name="link5_resp">
            <origin xyz="-0.038916 0.036337 0.027506" rpy="1.570796 3.141593 3.071779" />
            <geometry>
                <mesh filename="file:///home/rosqiu/coppelia_control/src/cs_hardware_interface/urdf/exported_panda_link5_resp_coll_2.dae" />
            </geometry>
        </collision>
        <collision name="link5_resp">
            <origin xyz="-0.038916 0.036337 0.027506" rpy="1.570796 3.141593 3.071779" />
            <geometry>
                <mesh filename="file:///home/rosqiu/coppelia_control/src/cs_hardware_interface/urdf/exported_panda_link5_resp_coll_3.dae" />
            </geometry>
        </collision>
        <collision name="link5_resp">
            <origin xyz="-0.038916 0.036337 0.027506" rpy="1.570796 3.141593 3.071779" />
            <geometry>
                <mesh filename="file:///home/rosqiu/coppelia_control/src/cs_hardware_interface/urdf/exported_panda_link5_resp_coll_4.dae" />
            </geometry>
        </collision>
        <collision name="link5_resp">
            <origin xyz="-0.038916 0.036337 0.027506" rpy="1.570796 3.141593 3.071779" />
            <geometry>
                <mesh filename="file:///home/rosqiu/coppelia_control/src/cs_hardware_interface/urdf/exported_panda_link5_resp_coll_5.dae" />
            </geometry>
        </collision>
        <collision name="link5_resp">
            <origin xyz="-0.038916 0.036337 0.027506" rpy="1.570796 3.141593 3.071779" />
            <geometry>
                <mesh filename="file:///home/rosqiu/coppelia_control/src/cs_hardware_interface/urdf/exported_panda_link5_resp_coll_6.dae" />
            </geometry>
        </collision>
        <visual name="link">
            <origin xyz="-0.039111 0.036345 0.027485" rpy="1.570796 3.141593 3.071779" />
            <geometry>
                <mesh filename="file:///home/rosqiu/coppelia_control/src/cs_hardware_interface/urdf/exported_panda_link_5_vis_1.dae" />
            </geometry>
            <material name="link_5_material">
                <color rgba="1.000000 1.000000 1.000000 1.0" />
            </material>
        </visual>
        <visual name="link">
            <origin xyz="-0.039111 0.036345 0.027485" rpy="1.570796 3.141593 3.071779" />
            <geometry>
                <mesh filename="file:///home/rosqiu/coppelia_control/src/cs_hardware_interface/urdf/exported_panda_link_5_vis_2.dae" />
            </geometry>
            <material name="link_5_material">
                <color rgba="0.250000 0.250000 0.250000 1.0" />
            </material>
        </visual>
    </link>
    <joint name="panda_joint5" type="revolute">
        <axis xyz="0 0 1" />
        <limit velocity="2.610000371933" lower="-2.8972465991974" effort="12.0" upper="2.8972465991974" />
        <parent link="link5_resp" />
        <child link="link6_resp" />
        <origin xyz="-0.055513 0.388820 -0.000000" rpy="1.570796 3.141593 3.071779" />
    </joint>
    <link name="link6_resp">
        <inertial>
            <origin xyz="0.000101 0.038651 -0.110916" rpy="3.141593 3.141592 3.141592" />
            <inertia ixy="6.5734913571839e-07" ixx="0.03988537400492" izz="0.010430599214868" iyz="-0.0078141474579038" iyy="0.036230106859883" ixz="-2.672442414716e-05" />
            <mass value="1.2259459495544" />
        </inertial>
        <collision name="link6_resp">
            <origin xyz="0.000168 0.037213 -0.105096" rpy="3.141593 3.141592 3.141592" />
            <geometry>
                <mesh filename="file:///home/rosqiu/coppelia_control/src/cs_hardware_interface/urdf/exported_panda_link6_resp_coll_1.dae" />
            </geometry>
        </collision>
        <collision name="link6_resp">
            <origin xyz="0.000168 0.037213 -0.105096" rpy="3.141593 3.141592 3.141592" />
            <geometry>
                <mesh filename="file:///home/rosqiu/coppelia_control/src/cs_hardware_interface/urdf/exported_panda_link6_resp_coll_2.dae" />
            </geometry>
        </collision>
        <collision name="link6_resp">
            <origin xyz="0.000168 0.037213 -0.105096" rpy="3.141593 3.141592 3.141592" />
            <geometry>
                <mesh filename="file:///home/rosqiu/coppelia_control/src/cs_hardware_interface/urdf/exported_panda_link6_resp_coll_3.dae" />
            </geometry>
        </collision>
        <collision name="link6_resp">
            <origin xyz="0.000168 0.037213 -0.105096" rpy="3.141593 3.141592 3.141592" />
            <geometry>
                <mesh filename="file:///home/rosqiu/coppelia_control/src/cs_hardware_interface/urdf/exported_panda_link6_resp_coll_4.dae" />
            </geometry>
        </collision>
        <collision name="link6_resp">
            <origin xyz="0.000168 0.037213 -0.105096" rpy="3.141593 3.141592 3.141592" />
            <geometry>
                <mesh filename="file:///home/rosqiu/coppelia_control/src/cs_hardware_interface/urdf/exported_panda_link6_resp_coll_5.dae" />
            </geometry>
        </collision>
        <collision name="link6_resp">
            <origin xyz="0.000168 0.037213 -0.105096" rpy="3.141593 3.141592 3.141592" />
            <geometry>
                <mesh filename="file:///home/rosqiu/coppelia_control/src/cs_hardware_interface/urdf/exported_panda_link6_resp_coll_6.dae" />
            </geometry>
        </collision>
        <collision name="link6_resp">
            <origin xyz="0.000168 0.037213 -0.105096" rpy="3.141593 3.141592 3.141592" />
            <geometry>
                <mesh filename="file:///home/rosqiu/coppelia_control/src/cs_hardware_interface/urdf/exported_panda_link6_resp_coll_7.dae" />
            </geometry>
        </collision>
        <collision name="link6_resp">
            <origin xyz="0.000168 0.037213 -0.105096" rpy="3.141593 3.141592 3.141592" />
            <geometry>
                <mesh filename="file:///home/rosqiu/coppelia_control/src/cs_hardware_interface/urdf/exported_panda_link6_resp_coll_8.dae" />
            </geometry>
        </collision>
        <collision name="link6_resp">
            <origin xyz="0.000168 0.037213 -0.105096" rpy="3.141593 3.141592 3.141592" />
            <geometry>
                <mesh filename="file:///home/rosqiu/coppelia_control/src/cs_hardware_interface/urdf/exported_panda_link6_resp_coll_9.dae" />
            </geometry>
        </collision>
        <visual name="link">
            <origin xyz="-0.000025 0.037473 -0.105129" rpy="3.141593 3.141592 3.141592" />
            <geometry>
                <mesh filename="file:///home/rosqiu/coppelia_control/src/cs_hardware_interface/urdf/exported_panda_link_6_vis_1.dae" />
            </geometry>
            <material name="link_6_material">
                <color rgba="1.000000 1.000000 1.000000 1.0" />
            </material>
        </visual>
        <visual name="link">
            <origin xyz="-0.000025 0.037473 -0.105129" rpy="3.141593 3.141592 3.141592" />
            <geometry>
                <mesh filename="file:///home/rosqiu/coppelia_control/src/cs_hardware_interface/urdf/exported_panda_link_6_vis_2.dae" />
            </geometry>
            <material name="link_6_material">
                <color rgba="0.250000 0.250000 0.250000 1.0" />
            </material>
        </visual>
    </link>
    <joint name="panda_joint6" type="revolute">
        <axis xyz="0 0 1" />
        <limit velocity="2.610000371933" lower="-0.017453292384744" effort="12.0" upper="3.7524577584118" />
        <parent link="link6_resp" />
        <child link="link7_resp" />
        <origin xyz="-0.000000 -0.000000 0.000000" rpy="-1.570796 3.141593 -3.141593" />
    </joint>
    <link name="link7_resp">
        <inertial>
            <origin xyz="0.050819 0.005558 0.005395" rpy="1.570796 3.141593 3.141593" />
            <inertia ixy="-0.00057744119112155" ixx="0.0046587251169735" izz="0.0070729035771789" iyz="-6.1476550160376e-05" iyy="0.008643924526682" ixz="-0.00030740988325929" />
            <mass value="1.6665550470352" />
        </inertial>
        <collision name="link7_resp">
            <origin xyz="0.042191 0.013607 0.005347" rpy="1.570796 3.141593 3.141593" />
            <geometry>
                <mesh filename="file:///home/rosqiu/coppelia_control/src/cs_hardware_interface/urdf/exported_panda_link7_resp_coll_1.dae" />
            </geometry>
        </collision>
        <collision name="link7_resp">
            <origin xyz="0.042191 0.013607 0.005347" rpy="1.570796 3.141593 3.141593" />
            <geometry>
                <mesh filename="file:///home/rosqiu/coppelia_control/src/cs_hardware_interface/urdf/exported_panda_link7_resp_coll_2.dae" />
            </geometry>
        </collision>
        <collision name="link7_resp">
            <origin xyz="0.042191 0.013607 0.005347" rpy="1.570796 3.141593 3.141593" />
            <geometry>
                <mesh filename="file:///home/rosqiu/coppelia_control/src/cs_hardware_interface/urdf/exported_panda_link7_resp_coll_3.dae" />
            </geometry>
        </collision>
        <collision name="link7_resp">
            <origin xyz="0.042191 0.013607 0.005347" rpy="1.570796 3.141593 3.141593" />
            <geometry>
                <mesh filename="file:///home/rosqiu/coppelia_control/src/cs_hardware_interface/urdf/exported_panda_link7_resp_coll_4.dae" />
            </geometry>
        </collision>
        <collision name="link7_resp">
            <origin xyz="0.042191 0.013607 0.005347" rpy="1.570796 3.141593 3.141593" />
            <geometry>
                <mesh filename="file:///home/rosqiu/coppelia_control/src/cs_hardware_interface/urdf/exported_panda_link7_resp_coll_5.dae" />
            </geometry>
        </collision>
        <collision name="link7_resp">
            <origin xyz="0.042191 0.013607 0.005347" rpy="1.570796 3.141593 3.141593" />
            <geometry>
                <mesh filename="file:///home/rosqiu/coppelia_control/src/cs_hardware_interface/urdf/exported_panda_link7_resp_coll_6.dae" />
            </geometry>
        </collision>
        <collision name="link7_resp">
            <origin xyz="0.042191 0.013607 0.005347" rpy="1.570796 3.141593 3.141593" />
            <geometry>
                <mesh filename="file:///home/rosqiu/coppelia_control/src/cs_hardware_interface/urdf/exported_panda_link7_resp_coll_7.dae" />
            </geometry>
        </collision>
        <collision name="link7_resp">
            <origin xyz="0.042191 0.013607 0.005347" rpy="1.570796 3.141593 3.141593" />
            <geometry>
                <mesh filename="file:///home/rosqiu/coppelia_control/src/cs_hardware_interface/urdf/exported_panda_link7_resp_coll_8.dae" />
            </geometry>
        </collision>
        <collision name="link7_resp">
            <origin xyz="0.042191 0.013607 0.005347" rpy="1.570796 3.141593 3.141593" />
            <geometry>
                <mesh filename="file:///home/rosqiu/coppelia_control/src/cs_hardware_interface/urdf/exported_panda_link7_resp_coll_9.dae" />
            </geometry>
        </collision>
        <collision name="link7_resp">
            <origin xyz="0.042191 0.013607 0.005347" rpy="1.570796 3.141593 3.141593" />
            <geometry>
                <mesh filename="file:///home/rosqiu/coppelia_control/src/cs_hardware_interface/urdf/exported_panda_link7_resp_coll_10.dae" />
            </geometry>
        </collision>
        <collision name="link7_resp">
            <origin xyz="0.042191 0.013607 0.005347" rpy="1.570796 3.141593 3.141593" />
            <geometry>
                <mesh filename="file:///home/rosqiu/coppelia_control/src/cs_hardware_interface/urdf/exported_panda_link7_resp_coll_11.dae" />
            </geometry>
        </collision>
        <collision name="link7_resp">
            <origin xyz="0.042191 0.013607 0.005347" rpy="1.570796 3.141593 3.141593" />
            <geometry>
                <mesh filename="file:///home/rosqiu/coppelia_control/src/cs_hardware_interface/urdf/exported_panda_link7_resp_coll_12.dae" />
            </geometry>
        </collision>
        <collision name="link7_resp">
            <origin xyz="0.042191 0.013607 0.005347" rpy="1.570796 3.141593 3.141593" />
            <geometry>
                <mesh filename="file:///home/rosqiu/coppelia_control/src/cs_hardware_interface/urdf/exported_panda_link7_resp_coll_13.dae" />
            </geometry>
        </collision>
        <collision name="link7_resp">
            <origin xyz="0.042191 0.013607 0.005347" rpy="1.570796 3.141593 3.141593" />
            <geometry>
                <mesh filename="file:///home/rosqiu/coppelia_control/src/cs_hardware_interface/urdf/exported_panda_link7_resp_coll_14.dae" />
            </geometry>
        </collision>
        <collision name="link7_resp">
            <origin xyz="0.042191 0.013607 0.005347" rpy="1.570796 3.141593 3.141593" />
            <geometry>
                <mesh filename="file:///home/rosqiu/coppelia_control/src/cs_hardware_interface/urdf/exported_panda_link7_resp_coll_15.dae" />
            </geometry>
        </collision>
        <collision name="link7_resp">
            <origin xyz="0.042191 0.013607 0.005347" rpy="1.570796 3.141593 3.141593" />
            <geometry>
                <mesh filename="file:///home/rosqiu/coppelia_control/src/cs_hardware_interface/urdf/exported_panda_link7_resp_coll_16.dae" />
            </geometry>
        </collision>
        <visual name="link">
            <origin xyz="0.042086 0.013418 0.005372" rpy="1.570796 3.141593 3.141592" />
            <geometry>
                <mesh filename="file:///home/rosqiu/coppelia_control/src/cs_hardware_interface/urdf/exported_panda_link_7_vis_1.dae" />
            </geometry>
            <material name="link_7_material">
                <color rgba="1.000000 1.000000 1.000000 1.0" />
            </material>
        </visual>
        <visual name="link">
            <origin xyz="0.042086 0.013418 0.005372" rpy="1.570796 3.141593 3.141592" />
            <geometry>
                <mesh filename="file:///home/rosqiu/coppelia_control/src/cs_hardware_interface/urdf/exported_panda_link_7_vis_2.dae" />
            </geometry>
            <material name="link_7_material">
                <color rgba="0.250000 0.250000 0.250000 1.0" />
            </material>
        </visual>
    </link>
    <joint name="panda_joint7" type="revolute">
        <axis xyz="0 0 1" />
        <limit velocity="2.610000371933" lower="-2.8972465991974" effort="12.0" upper="2.8972465991974" />
        <parent link="link7_resp" />
        <child link="link8_resp" />
        <origin xyz="0.088000 0.000000 -0.000000" rpy="-1.570796 3.141592 3.141593" />
    </joint>
    <link name="link8_resp">
        <inertial>
            <origin xyz="-0.000077 -0.000876 0.078618" rpy="-0.000000 3.141593 -3.141592" />
            <inertia ixy="7.6321250755392e-11" ixx="0.0088670116631003" izz="0.01180331651387" iyz="-9.1760218741593e-08" iyy="0.0088670122123097" ixz="7.00227187462e-07" />
            <mass value="0.73552197217941" />
        </inertial>
        <collision name="link8_resp">
            <origin xyz="-0.000057 -0.000873 0.103159" rpy="0.000000 3.141593 -0.595144" />
            <geometry>
                <cylinder length="0.0095007419586182" radius="0.030879393219948" />
            </geometry>
        </collision>
        <collision name="link8_resp">
            <origin xyz="-0.000079 -0.000876 0.076009" rpy="-0.000002 3.141594 -2.065463" />
            <geometry>
                <cylinder length="0.045800685882568" radius="0.043132938444614" />
            </geometry>
        </collision>
        <visual name="link">
            <origin xyz="-0.000079 -0.000877 0.080509" rpy="-0.000000 3.141593 -3.141592" />
            <geometry>
                <mesh filename="file:///home/rosqiu/coppelia_control/src/cs_hardware_interface/urdf/exported_panda_link_8_vis_1.dae" />
            </geometry>
            <material name="link_8_material">
                <color rgba="1.000000 1.000000 1.000000 1.0" />
            </material>
        </visual>
    </link>
    <joint name="connection" type="fixed">
        <axis xyz="0 0 1" />
        <parent link="link8_resp" />
        <child link="FrankaGripper" />
        <origin xyz="-0.000271 0.000012 0.107001" rpy="3.141593 3.141593 -3.141592" />
    </joint>
    <link name="FrankaGripper">
        <inertial>
            <origin xyz="0.007993 0.005362 0.000301" rpy="-3.141593 3.141593 -3.141593" />
            <inertia ixy="-0.000236301420585" ixx="0.00055136998466875" izz="0.0005356164140933" iyz="-3.041173254942e-18" iyy="0.0005513698709592" ixz="6.4988166909013e-18" />
            <mass value="0.23000000417233" />
        </inertial>
        <collision name="FrankaGripper">
            <origin xyz="0.000000 0.000000 0.000000" rpy="-3.141593 3.141593 -3.141593" />
            <geometry>
                <mesh filename="file:///home/rosqiu/coppelia_control/src/cs_hardware_interface/urdf/exported_panda_FrankaGripper_coll_1.dae" />
            </geometry>
        </collision>
        <collision name="FrankaGripper">
            <origin xyz="0.000000 0.000000 0.000000" rpy="-3.141593 3.141593 -3.141593" />
            <geometry>
                <mesh filename="file:///home/rosqiu/coppelia_control/src/cs_hardware_interface/urdf/exported_panda_FrankaGripper_coll_2.dae" />
            </geometry>
        </collision>
        <collision name="FrankaGripper">
            <origin xyz="0.000000 0.000000 0.000000" rpy="-3.141593 3.141593 -3.141593" />
            <geometry>
                <mesh filename="file:///home/rosqiu/coppelia_control/src/cs_hardware_interface/urdf/exported_panda_FrankaGripper_coll_3.dae" />
            </geometry>
        </collision>
        <visual name="visible">
            <origin xyz="0.000000 0.001224 -0.002953" rpy="-3.141593 3.141593 -3.141593" />
            <geometry>
                <mesh filename="file:///home/rosqiu/coppelia_control/src/cs_hardware_interface/urdf/exported_panda_visible_vis_1.dae" />
            </geometry>
            <material name="visible_material">
                <color rgba="1.000000 1.000000 1.000000 1.0" />
            </material>
        </visual>
    </link>
    <joint name="centerJoint" type="prismatic">
        <axis xyz="0 0 1" />
        <limit velocity="0.10000000149012" lower="0.0" effort="20.0" upper="0.041000001132488" />
        <parent link="FrankaGripper" />
        <child link="leftFinger" />
        <origin xyz="0.000168 0.001495 0.074931" rpy="-1.571080 3.141811 3.141556" />
    </joint>
    <link name="leftFinger">
        <inertial>
            <origin xyz="0.000040 -0.024567 0.012277" rpy="-2.915859 4.704142 1.342121" />
            <inertia ixy="-1.0258588401084e-07" ixx="0.00018852426788335" izz="5.5836018162053e-05" iyz="2.6465682920481e-07" iyy="0.00018639074698225" ixz="6.9071240866037e-06" />
            <mass value="0.125" />
        </inertial>
        <collision name="leftFinger">
            <origin xyz="0.000080 -0.017999 0.012501" rpy="-2.915859 4.704142 1.342121" />
            <geometry>
                <mesh filename="file:///home/rosqiu/coppelia_control/src/cs_hardware_interface/urdf/exported_panda_leftFinger_coll_1.dae" />
            </geometry>
        </collision>
        <collision name="leftFinger">
            <origin xyz="0.000080 -0.017999 0.012501" rpy="-2.915859 4.704142 1.342121" />
            <geometry>
                <mesh filename="file:///home/rosqiu/coppelia_control/src/cs_hardware_interface/urdf/exported_panda_leftFinger_coll_2.dae" />
            </geometry>
        </collision>
        <collision name="leftFinger">
            <origin xyz="0.000080 -0.017999 0.012501" rpy="-2.915859 4.704142 1.342121" />
            <geometry>
                <mesh filename="file:///home/rosqiu/coppelia_control/src/cs_hardware_interface/urdf/exported_panda_leftFinger_coll_3.dae" />
            </geometry>
        </collision>
        <collision name="leftFinger">
            <origin xyz="0.000080 -0.017999 0.012501" rpy="-2.915859 4.704142 1.342121" />
            <geometry>
                <mesh filename="file:///home/rosqiu/coppelia_control/src/cs_hardware_interface/urdf/exported_panda_leftFinger_coll_4.dae" />
            </geometry>
        </collision>
        <collision name="leftFinger">
            <origin xyz="0.000080 -0.017999 0.012501" rpy="-2.915859 4.704142 1.342121" />
            <geometry>
                <mesh filename="file:///home/rosqiu/coppelia_control/src/cs_hardware_interface/urdf/exported_panda_leftFinger_coll_5.dae" />
            </geometry>
        </collision>
        <collision name="leftFinger">
            <origin xyz="0.000080 -0.017999 0.012501" rpy="-2.915859 4.704142 1.342121" />
            <geometry>
                <mesh filename="file:///home/rosqiu/coppelia_control/src/cs_hardware_interface/urdf/exported_panda_leftFinger_coll_6.dae" />
            </geometry>
        </collision>
        <collision name="leftFinger">
            <origin xyz="0.000080 -0.017999 0.012501" rpy="-2.915859 4.704142 1.342121" />
            <geometry>
                <mesh filename="file:///home/rosqiu/coppelia_control/src/cs_hardware_interface/urdf/exported_panda_leftFinger_coll_7.dae" />
            </geometry>
        </collision>
        <collision name="leftFinger">
            <origin xyz="0.000080 -0.017999 0.012501" rpy="-2.915859 4.704142 1.342121" />
            <geometry>
                <mesh filename="file:///home/rosqiu/coppelia_control/src/cs_hardware_interface/urdf/exported_panda_leftFinger_coll_8.dae" />
            </geometry>
        </collision>
        <collision name="leftFinger">
            <origin xyz="0.000080 -0.017999 0.012501" rpy="-2.915859 4.704142 1.342121" />
            <geometry>
                <mesh filename="file:///home/rosqiu/coppelia_control/src/cs_hardware_interface/urdf/exported_panda_leftFinger_coll_9.dae" />
            </geometry>
        </collision>
        <visual name="leftFinger_visible">
            <origin xyz="0.000031 -0.017953 0.012297" rpy="1.571080 3.141556 3.141374" />
            <geometry>
                <mesh filename="file:///home/rosqiu/coppelia_control/src/cs_hardware_interface/urdf/exported_panda_leftFinger_visible_vis_1.dae" />
            </geometry>
            <material name="leftFinger_visible_material">
                <color rgba="0.660000 0.670000 0.680000 1.0" />
            </material>
        </visual>
    </link>
    <joint name="leftFingerPad_connection" type="fixed">
        <axis xyz="0 0 1" />
        <parent link="leftFinger" />
        <child link="leftPad" />
        <origin xyz="0.000028 0.000055 0.006728" rpy="-0.000001 3.141593 -1.570796" />
    </joint>
    <link name="leftPad">
        <inertial>
            <origin xyz="-0.000346 0.000007 0.002414" rpy="1.575077 1.575863 0.007296" />
            <inertia ixy="1.6213889016144e-07" ixx="0.00016691092146122" izz="0.00010804066386562" iyz="2.2431666371765e-08" iyy="0.00010830756544703" ixz="4.1543267577368e-08" />
            <mass value="0.125" />
        </inertial>
        <collision name="leftPad">
            <origin xyz="-0.000078 0.000000 0.002456" rpy="1.575077 1.575863 0.007296" />
            <geometry>
                <mesh filename="file:///home/rosqiu/coppelia_control/src/cs_hardware_interface/urdf/exported_panda_leftPad_coll_1.dae" />
            </geometry>
        </collision>
        <visual name="leftPad_visible">
            <origin xyz="-0.000106 -0.000024 0.002434" rpy="-1.570513 3.141630 -1.570577" />
            <geometry>
                <mesh filename="file:///home/rosqiu/coppelia_control/src/cs_hardware_interface/urdf/exported_panda_leftPad_visible_vis_1.dae" />
            </geometry>
            <material name="leftPad_visible_material">
                <color rgba="0.200000 0.200000 0.200000 1.0" />
            </material>
        </visual>
    </link>
    <joint name="openCloseJoint" type="prismatic">
        <axis xyz="0 0 1" />
        <limit velocity="10.0" lower="0.0" effort="20.0" upper="0.082000002264977" />
        <parent link="leftFinger" />
        <child link="rightFinger" />
        <origin xyz="-0.000000 -0.000000 -0.000000" rpy="0.000033 3.141592 0.000000" />
    </joint>
    <link name="rightFinger">
        <inertial>
            <origin xyz="0.000022 -0.024520 0.011668" rpy="3.062975 1.579239 -1.647380" />
            <inertia ixy="3.8961991153265e-08" ixx="0.00018875818524776" izz="5.5596183740278e-05" iyz="-6.110250389809e-08" iyy="0.00018660159563509" ixz="-5.2355363902135e-06" />
            <mass value="0.125" />
        </inertial>
        <collision name="rightFinger">
            <origin xyz="0.000006 -0.017987 0.011625" rpy="3.062975 1.579239 -1.647380" />
            <geometry>
                <mesh filename="file:///home/rosqiu/coppelia_control/src/cs_hardware_interface/urdf/exported_panda_rightFinger_coll_1.dae" />
            </geometry>
        </collision>
        <collision name="rightFinger">
            <origin xyz="0.000006 -0.017987 0.011625" rpy="3.062975 1.579239 -1.647380" />
            <geometry>
                <mesh filename="file:///home/rosqiu/coppelia_control/src/cs_hardware_interface/urdf/exported_panda_rightFinger_coll_2.dae" />
            </geometry>
        </collision>
        <collision name="rightFinger">
            <origin xyz="0.000006 -0.017987 0.011625" rpy="3.062975 1.579239 -1.647380" />
            <geometry>
                <mesh filename="file:///home/rosqiu/coppelia_control/src/cs_hardware_interface/urdf/exported_panda_rightFinger_coll_3.dae" />
            </geometry>
        </collision>
        <collision name="rightFinger">
            <origin xyz="0.000006 -0.017987 0.011625" rpy="3.062975 1.579239 -1.647380" />
            <geometry>
                <mesh filename="file:///home/rosqiu/coppelia_control/src/cs_hardware_interface/urdf/exported_panda_rightFinger_coll_4.dae" />
            </geometry>
        </collision>
        <collision name="rightFinger">
            <origin xyz="0.000006 -0.017987 0.011625" rpy="3.062975 1.579239 -1.647380" />
            <geometry>
                <mesh filename="file:///home/rosqiu/coppelia_control/src/cs_hardware_interface/urdf/exported_panda_rightFinger_coll_5.dae" />
            </geometry>
        </collision>
        <collision name="rightFinger">
            <origin xyz="0.000006 -0.017987 0.011625" rpy="3.062975 1.579239 -1.647380" />
            <geometry>
                <mesh filename="file:///home/rosqiu/coppelia_control/src/cs_hardware_interface/urdf/exported_panda_rightFinger_coll_6.dae" />
            </geometry>
        </collision>
        <collision name="rightFinger">
            <origin xyz="0.000006 -0.017987 0.011625" rpy="3.062975 1.579239 -1.647380" />
            <geometry>
                <mesh filename="file:///home/rosqiu/coppelia_control/src/cs_hardware_interface/urdf/exported_panda_rightFinger_coll_7.dae" />
            </geometry>
        </collision>
        <collision name="rightFinger">
            <origin xyz="0.000006 -0.017987 0.011625" rpy="3.062975 1.579239 -1.647380" />
            <geometry>
                <mesh filename="file:///home/rosqiu/coppelia_control/src/cs_hardware_interface/urdf/exported_panda_rightFinger_coll_8.dae" />
            </geometry>
        </collision>
        <collision name="rightFinger">
            <origin xyz="0.000006 -0.017987 0.011625" rpy="3.062975 1.579239 -1.647380" />
            <geometry>
                <mesh filename="file:///home/rosqiu/coppelia_control/src/cs_hardware_interface/urdf/exported_panda_rightFinger_coll_9.dae" />
            </geometry>
        </collision>
        <visual name="rightFinger_visible">
            <origin xyz="0.000040 -0.018035 0.011413" rpy="-1.570480 3.141630 0.000219" />
            <geometry>
                <mesh filename="file:///home/rosqiu/coppelia_control/src/cs_hardware_interface/urdf/exported_panda_rightFinger_visible_vis_1.dae" />
            </geometry>
            <material name="rightFinger_visible_material">
                <color rgba="0.660000 0.670000 0.680000 1.0" />
            </material>
        </visual>
    </link>
    <joint name="rightFingerPad_connection" type="fixed">
        <axis xyz="0 0 1" />
        <parent link="rightFinger" />
        <child link="rightPad" />
        <origin xyz="-0.000102 0.000143 0.006578" rpy="0.000034 3.124728 1.574869" />
    </joint>
    <link name="rightPad">
        <inertial>
            <origin xyz="0.000346 -0.000006 0.002414" rpy="1.567081 4.707277 0.006731" />
            <inertia ixy="-1.6640883230316e-07" ixx="0.00016691049501109" izz="0.00010804302982103" iyz="-1.963717353832e-08" iyy="0.00010830547761067" ixz="4.1290464104407e-08" />
            <mass value="0.125" />
        </inertial>
        <collision name="rightPad">
            <origin xyz="0.000078 -0.000000 0.002457" rpy="1.567081 4.707277 0.006731" />
            <geometry>
                <mesh filename="file:///home/rosqiu/coppelia_control/src/cs_hardware_interface/urdf/exported_panda_rightPad_coll_1.dae" />
            </geometry>
        </collision>
        <visual name="rightPad_visible">
            <origin xyz="0.000155 -0.000007 0.002420" rpy="1.587977 3.141586 -1.566943" />
            <geometry>
                <mesh filename="file:///home/rosqiu/coppelia_control/src/cs_hardware_interface/urdf/exported_panda_rightPad_visible_vis_1.dae" />
            </geometry>
            <material name="rightPad_visible_material">
                <color rgba="0.200000 0.200000 0.200000 1.0" />
            </material>
        </visual>
    </link>
</robot>
